<?xml version="1.0"?>
<robot xmlns:sensor="http://playerstage.sourceforge.net/gazebo/xmlschema/#sensor"
       xmlns:controller="http://playerstage.sourceforge.net/gazebo/xmlschema/#controller"
       xmlns:interface="http://playerstage.sourceforge.net/gazebo/xmlschema/#interface">

  <include filename="$(find ias_robot_defs)/defs/util_defs.xml"/>
  <include filename="$(find ias_robot_defs)/defs/b21/powercube_defs.xml"/>
  <include filename="$(find ias_robot_defs)/defs/b21/powercube_gripper_defs.xml"/>
  
  <macro name="left_arm" params="parent name *origin">
    <!-- First (shoulder) element of the arm. Fixed to its parent. -->
    <joint name="${parent}_${name}_arm_base_joint" type="fixed">
      <insert_block name="origin"/>
      <parent link="${parent}_link"/>
      <child link="${name}_arm_base_link"/>
    </joint>

    <link name="${name}_arm_base_link">
      <inertial>
        <mass value="${arm_elem_90_mass + arm_separator_1_mass}"/>
        <origin rpy="0 0 0" xyz="0 0 0"/>
        <cuboid_inertia_def length="0.120" width="0.135" height="0.090"
                            mass="${arm_elem_90_mass + arm_separator_1_mass}"/>
      </inertial>

      <visual>
        <origin xyz="0 0 0" rpy="${-M_PI/2} 0 0"/>
        <geometry>
          <mesh filename="b21/link0.stl"/>
        </geometry>
      </visual>
      <collision>
        <origin xyz="-0.015 -0.0225 0" rpy="0 0 0"/>
        <geometry>
          <box size="0.120 0.135 0.090"/>
        </geometry>
      </collision>
    </link>

    <gazebo reference="${name}_arm_base_link">
      <material value="powercube-arm.material"/>
    </gazebo>

    <!--
       Second segment of the arm. Joint along z-axis
      -->
    <joint name="${name}_arm_1_joint" type="revolute">
      <origin xyz="0 0 -0.225" rpy="0 0 0"/>
      <axis xyz="0 0 1"/>
      <limit lower="${-266 * M_PI/2}" upper="${266 * M_PI/2}"
             effort="206" velocity="${149 * M_PI/2}" />
      <dynamics damping="1.0"/>
      <safety_controller k_velocity="1.5" k_position="100"
                         soft_lower_limit="${-266 * M_PI / 180 + 0.1}"
                         soft_upper_limit="${266 * M_PI / 180 - 0.1}"/>
      <parent link="${name}_arm_base_link"/>
      <child link="${name}_arm_1_link"/>
    </joint>

    <link name="${name}_arm_1_link">
      <inertial>
        <mass value="${2 * arm_elem_90_mass + arm_separator_2_mass}"/>
        <origin rpy="0 0 0" xyz="0 0 0"/>
        <cuboid_inertia_def length="0.12" width="0.090" height="0.225"
                            mass="${2 * arm_elem_90_mass + arm_separator_2_mass}"/>
      </inertial>

      <visual>
        <origin xyz="0 0 0" rpy="${M_PI} 0 0"/>
        <geometry>
          <mesh filename="b21/link1.stl"/>
        </geometry>
      </visual>

      <collision>
        <origin xyz="-0.015 0 0.0675" rpy="0 0 0"/>
        <geometry>
          <box size="0.120 0.090 0.225"/>
        </geometry>
      </collision>
    </link>

    <transmission name="${name}_arm_1_trans" type="SimpleTransmission">
      <actuator name="${name}_arm_1_motor"/>
      <joint name="${name}_arm_1_joint"/>
      <mechanicalReduction>1.0</mechanicalReduction>
    </transmission>

    <gazebo reference="${name}_arm_1_link">
      <material value="powercube-arm.material"/>
    </gazebo>

    <!-- 
	   Third segment of the arm. Joint along y-axis
      -->
    <joint name="${name}_arm_2_joint" type="revolute">
      <origin xyz="0 -0.26 0" rpy="0 0 0"/>
      <axis xyz="0 1 0"/>
      <limit lower="${-266 * M_PI/2}" upper="${266 * M_PI/2}"
             effort="206" velocity="${149 * M_PI/2}" />
      <dynamics damping="1.0"/>
      <safety_controller k_velocity="1.5" k_position="100"
                         soft_lower_limit="${-266 * M_PI / 180 + 0.1}"
                         soft_upper_limit="${266 * M_PI / 180 - 0.1}"/>
      <parent link="${name}_arm_1_link"/>
      <child link="${name}_arm_2_link"/>
    </joint>

    <link name="${name}_arm_2_link">
      <inertial>
        <mass value="${arm_elem_90_mass + arm_elem_70_mass + arm_separator_3_mass}"/>
        <origin rpy="0 0 0" xyz="0 0 0"/>
        <cuboid_inertia_def length="0.090" width="0.250" height="0.090"
                            mass="${arm_elem_90_mass + arm_elem_70_mass + arm_separator_3_mass}"/>
      </inertial>

      <visual>
        <origin xyz="0 0.00 0" rpy="0 0 0"/>
        <geometry>
          <mesh filename="b21/link2.stl"/>
        </geometry>
      </visual>

      <collision>
        <origin xyz="0 0.09 0" rpy="0 0 0"/>
        <geometry>
          <box size="0.090 0.250 0.090"/>
        </geometry>
      </collision>
    </link>

    <transmission name="${name}_arm_2_trans" type="SimpleTransmission">
      <actuator name="${name}_arm_2_motor"/>
      <joint name="${name}_arm_2_joint"/>
      <mechanicalReduction>1.0</mechanicalReduction>
    </transmission>

    <gazebo reference="${name}_arm_2_link">
      <material value="powercube-arm.material"/>
    </gazebo>

    <!-- 
	   Fourth element of the arm. z-axis
      -->
    <joint name="${name}_arm_3_joint" type="revolute">
      <origin xyz="0 0 0" rpy="0 0 0"/>
      <axis xyz="1 0 0"/>
      <limit lower="${-118 * M_PI/2}" upper="${118 * M_PI/2}"
             effort="73" velocity="${149 * M_PI/2}" />
      <dynamics damping="1.0"/>
      <safety_controller k_velocity="1.5" k_position="100"
                         soft_lower_limit="${-118 * M_PI / 180 + 0.1}"
                         soft_upper_limit="${118 * M_PI / 180 - 0.1}"/>
      <parent link="${name}_arm_2_link"/>
      <child link="${name}_arm_3_link"/>
    </joint>

    <link name="${name}_arm_3_link">
      <inertial>
        <mass value="${2 * arm_elem_70_mass + arm_separator_4_mass}"/>
        <origin rpy="0 0 0" xyz="0 -0.10 0"/>
        <cuboid_inertia_def length="0.140" width="0.170" height="0.100"
                            mass="${2 * arm_elem_70_mass + arm_separator_4_mass}"/>
      </inertial>
      <visual>
        <origin xyz="0 -0.10 0" rpy="0 0 0"/>
        <geometry>
          <mesh filename="b21/link3l.stl"/>
        </geometry>
      </visual>

      <collision>
        <origin xyz="-0.035 -0.05 -0.015" rpy="0 0 0"/>
        <geometry>
          <box size="0.140 0.170 0.100"/>
        </geometry>
      </collision>
    </link>

    <transmission name="${name}_arm_3_trans" type="SimpleTransmission">
      <actuator name="${name}_arm_3_motor"/>
      <joint name="${name}_arm_3_joint"/>
      <mechanicalReduction>1.0</mechanicalReduction>
    </transmission>

    <gazebo reference="${name}_arm_3_link">
      <material value="powercube-arm.material"/>
    </gazebo>

    <!-- 
	   Fifth element of the arm. x-axis
      -->
    <joint name="${name}_arm_4_joint" type="revolute">
      <origin xyz="0 -0.31 0" rpy="0 0 0"/>
      <axis xyz="0 1 0"/>
      <limit lower="${-266 * M_PI/2}" upper="${266 * M_PI/2}"
             effort="73" velocity="${149 * M_PI/2}" />
      <dynamics damping="1.0"/>
      <safety_controller k_velocity="1.5" k_position="100"
                         soft_lower_limit="${-266 * M_PI / 180 + 0.1}"
                         soft_upper_limit="${266 * M_PI / 180 - 0.1}"/>
      <parent link="${name}_arm_3_link"/>
      <child link="${name}_arm_4_link"/>
      
    </joint>

    <link name="${name}_arm_4_link">
      <inertial>
        <mass value="${arm_elem_70_mass + arm_elem_pw_mass/2 + arm_separator_5_mass}"/>
        <origin rpy="0 0 0" xyz="0 0 0"/>
        <cuboid_inertia_def length="0.160" width="0.212" height="0.100"
                            mass="${arm_elem_70_mass + arm_elem_pw_mass/2 + arm_separator_5_mass}"/>
      </inertial>

      <visual>
        <origin xyz="0 0 0" rpy="0 0 0"/>
        <geometry>
          <mesh filename="b21/link4l.stl"/>
        </geometry>
      </visual>

      <collision>
        <origin xyz="-0.008 0.069 -0.015" rpy="0 0 0"/>
        <geometry>
          <box size="0.160 0.212 0.100"/>
        </geometry>
      </collision>
    </link>

    <transmission name="${name}_arm_4_trans" type="SimpleTransmission">
      <actuator name="${name}_arm_4_motor"/>
      <joint name="${name}_arm_4_joint"/>
      <mechanicalReduction>1.0</mechanicalReduction>
    </transmission>

    <gazebo reference="${name}_arm_4_link">
      <material value="powercube-arm.material"/>
    </gazebo>

    <!-- 
	   Sixth element of the arm. z-axis
      -->
    <joint name="${name}_arm_5_joint" type="revolute">
      <origin xyz="0 0 0" rpy="0 0 0"/>
      <axis xyz="1 0 0"/>
      <limit lower="${-107 * M_PI/2}" upper="${107 * M_PI/2}"
             effort="35" velocity="${248 * M_PI/2}"/>
      <dynamics damping="1.0"/>
      <safety_controller k_velocity="1.5" k_position="100"
                         soft_lower_limit="${-107 * M_PI / 180 + 0.1}"
                         soft_upper_limit="${107 * M_PI / 180 - 0.1}"/>
      <parent link="${name}_arm_4_link"/>
      <child link="${name}_arm_5_link"/>
    </joint>
    
    <link name="${name}_arm_5_link">
      <inertial>
        <mass value="${arm_elem_pw_mass/2}"/>
        <origin rpy="0 0 0" xyz="0 0 0"/>
        <cuboid_inertia_def length="0.090" width="0.107" height="0.070"
                            mass="${arm_elem_pw_mass/2}"/>
      </inertial>

      <visual>
        <origin xyz="0 0 0" rpy="${-M_PI/2} 0 0"/>
        <geometry>
          <mesh filename="b21/link5.stl"/>
        </geometry>
      </visual>

      <collision>
        <origin xyz="0 0 0" rpy="0 0 0"/>
        <geometry>
          <box size="0.090 0.107 0.070"/>
        </geometry>
      </collision>
    </link>

    <transmission name="${name}_arm_5_trans" type="SimpleTransmission">
      <actuator name="${name}_arm_5_motor"/>
      <joint name="${name}_arm_5_joint"/>
      <mechanicalReduction>1.0</mechanicalReduction>
    </transmission>

    <gazebo reference="${name}_arm_5_link">
      <material value="powercube-arm.material"/>
    </gazebo>

    <!-- 
	   Seventh element of the arm. z-axis
      -->
    <joint name="${name}_arm_6_joint" type="revolute">
      <origin xyz="0 -0.265 0" rpy="${M_PI/2} ${M_PI/2} 0"/>      
      <axis xyz="0 1 0"/>
      <limit lower="${-266 * M_PI/2}" upper="${266 * M_PI/2}"
             effort="206" velocity="${149 * M_PI/2}" />
      <dynamics damping="1.0"/>
      <safety_controller k_velocity="1.5" k_position="100"
                         soft_lower_limit="${-266 * M_PI / 180 + 0.1}"
                         soft_upper_limit="${266 * M_PI / 180 - 0.1}"/>
      <parent link="${name}_arm_5_link"/>
      <child link="${name}_arm_6_link"/>
    </joint>

    <link name="${name}_arm_6_link">
      <inertial>
        <mass value="${arm_elem_gripper_mass}"/>
        <origin rpy="0 0 0" xyz="0 0 0"/>
        <cuboid_inertia_def length="0.140" width="0.210" height="0.080"
                            mass="${arm_elem_gripper_mass}"/>
      </inertial>

      <visual>
        <origin xyz="0 0 -0.07" rpy="${-M_PI/2} 0 ${M_PI/2}"/>
        <geometry>
          <mesh filename="b21/link6.stl"/>
        </geometry>
      </visual>

      <collision>
        <origin xyz="0 -0.015 -0.14" rpy="${-M_PI/2} 0 ${M_PI/2}"/>
        <geometry>
          <box size="0.140 0.140 0.080 "/>
        </geometry>
      </collision>
    </link>

    <transmission name="${name}_arm_6_trans" type="SimpleTransmission">
      <actuator name="${name}_arm_6_motor"/>
      <joint name="${name}_arm_6_joint"/>
      <mechanicalReduction>1.0</mechanicalReduction>
    </transmission>

    <gazebo reference="${name}_arm_6_link">
      <material value="powercube-arm.material"/>
    </gazebo>

    <!--
       Gripper
      -->
    <b21_gripper name="${name}" parent="${name}_arm_6_link"/>
    
  </macro>

</robot>
