<?xml version="1.0"?>
<robot xmlns:sensor="http://playerstage.sourceforge.net/gazebo/xmlschema/#sensor"
       xmlns:controller="http://playerstage.sourceforge.net/gazebo/xmlschema/#controller"
       xmlns:interface="http://playerstage.sourceforge.net/gazebo/xmlschema/#interface">

  <include filename="$(find ias_robot_defs)/defs/util_defs.xml"/>

  <property name="arm_elem_finger_mass" value="0.2"/>

  <macro name="b21_gripper" params="parent name">

    <joint name="${name}_gripper_1_joint" type="prismatic">
      <axis xyz="0 1 0"/>
      <origin xyz="0 0 -0.07" rpy="0 0 0"/>
      <limit lower="0" upper="0.045"
             velocity="1" effort="500"/>
      <dynamics damping="1.0"/>
      <parent link="${parent}"/>
      <child link="${name}_gripper_1_link"/>
    </joint>

    <link name="${name}_gripper_1_link">
      <inertial>
        <mass value="${arm_elem_finger_mass}"/>
        <origin xyz="0 0.01 0.035" rpy="0 0 0"/>
        <cuboid_inertia_def length="0.03" width="0.02" height="0.07"
                            mass="${arm_elem_finger_mass}"/>
      </inertial>

      <visual>
        <origin xyz="0 0.01 0.035" rpy="0 0 0"/>
        <geometry>
          <box size="0.03 0.02 0.07"/>
        </geometry>
      </visual>

      <collision>
        <origin xyz="0 0.01 0.035" rpy="0 0 0"/>
        <geometry>
          <box size="0.03 0.02 0.07"/>
        </geometry>
      </collision>
    </link>

    <gazebo reference="${name}_gripper_1_link">
      <material value="cube_light_gray"/>
    </gazebo>

    <joint name="${name}_gripper_2_joint" type="prismatic">
      <origin xyz="0 0 -0.07" rpy="0 0 0"/>
      <axis xyz="0 -1 0"/>
      <limit lower="0" upper="0.045"
             velocity="1" effort="500"/>
      <dynamicsy damping="1.0"/>
      <parent link="${parent}"/>
      <child link="${name}_gripper_2_link"/>
    </joint>

    <link name="${name}_gripper_2_link">
      <inertial>
        <mass value="${arm_elem_finger_mass}"/>
        <origin xyz="0 0 0.035"/>
        <cuboid_inertia_def length="0.03" width="0.02" height="0.07"
                            mass="${arm_elem_finger_mass}"/>
      </inertial>

      <visual>
        <origin xyz="0 -0.01 0.035" rpy="0 0 0"/>
        <geometry>
          <box size="0.03 0.02 0.07"/>
        </geometry>
      </visual>

      <collision>
        <origin xyz="0 -0.01 0.035" rpy="0 0 0"/>
        <geometry>
          <box size="0.03 0.02 0.07"/>
        </geometry>
      </collision>
    </link>

    <gazebo reference="${name}_gripper_2_link">
      <material value="cube_light_gray"/>
    </gazebo>

    <transmission type="GripperTransmission" name="${name}_gripper_transmission">
      <actuator name="${name}_gripper_motor" />
      <joint name="${name}_gripper_1_joint" preduction="1" ereduction="1"/>
      <joint name="${name}_gripper_2_joint" preduction="-1" ereduction="-1"/>
      <!-- GripTransmission uses a PID controller to keep the joint angles aligned in Gazebo -->
      <pid p="1.0" i="2.0" d="3.0" iClamp="2.0" /> <!-- Only needed for Gazebo -->
    </transmission>
    
  </macro>
  
</robot>

