<?xml version="1.0"?>
<robot xmlns:sensor="http://playerstage.sourceforge.net/gazebo/xmlschema/#sensor"
       xmlns:controller="http://playerstage.sourceforge.net/gazebo/xmlschema/#controller"
       xmlns:interface="http://playerstage.sourceforge.net/gazebo/xmlschema/#interface">

  <include filename="$(find rosie_description)/urdf/common/util_defs.xml"/>
  <include filename="$(find rosie_description)/urdf/common/gazebo_sensors.xml"/>  
  <include filename="$(find rosie_description)/urdf/powercube.urdf.xacro"/>

  <macro name="rosie_shoulder_laser" params="parent">
    <joint name="shoulder_tilt_fixed_joint" type="fixed">
      <origin xyz="${cal_base_to_neck_scanner_x}
                   ${cal_base_to_neck_scanner_y}
                   ${cal_base_to_neck_scanner_z}"
              rpy="${cal_base_to_neck_scanner_roll}
                   ${cal_base_to_neck_scanner_pitch}
                   ${cal_base_to_neck_scanner_yaw}"/>
      <parent link="${parent}"/>
      <child link="shoulder_tilt_base"/>
    </joint>

    <link name="shoulder_tilt_base">
      <inertial>
        <mass value="${0.5 * arm_elem_70_mass}"/>
        <cuboid_inertia_def length="0.07" width="0.07" height="0.07"
                            mass="${0.5 * arm_elem_70_mass}"/>
      </inertial>
      <visual>
        <origin xyz="0 0 0" rpy="0 0 0"/>
        <geometry>
          <box size="0.07 0.07 0.07"/>
        </geometry>
        <material name="Grey"/>
      </visual>
      <collision>
        <origin xyz="0 0 0" rpy="0 0 0"/>
        <geometry>
          <box size="0.07 0.07 0.07"/>
        </geometry>
      </collision>
    </link>
    <gazebo reference="shoulder_tilt_base">
      <material value="cube_light_gray"/>
    </gazebo>

    <joint name="shoulder_tilting_joint" type="revolute">
      <origin xyz="0 -0.070 0" rpy="0 0 0"/>
      <axis xyz="0 -1 0"/>
      <limit lower="-1.3" upper="1.3"
             effort="206" velocity="${149 * M_PI/2}"/>
      <parent link="shoulder_tilt_base"/>
      <child link="shoulder_tilt_end"/>
    </joint>

    <link name="shoulder_tilt_end">
      <inertial>
        <mass value="${0.5 * arm_elem_70_mass}"/>
        <cuboid_inertia_def length="0.07" width="0.07" height="0.07"
                            mass="${0.5 * arm_elem_70_mass}"/>
      </inertial>
      <visual>
        <origin xyz="0 0 0" rpy="0 0 0"/>
        <geometry>
          <box size="0.07 0.07 0.07"/>
        </geometry>
        <material name="Grey"/>
      </visual>
      <collision>
        <origin xyz="0 0 0" rpy="0 0 0"/>
        <geometry>
          <box size="0.07 0.07 0.07"/>
        </geometry>
      </collision>
    </link>
    <gazebo reference="shoulder_tilt_end">
      <material value="cube_light_gray"/>
    </gazebo>

    <transmission name="shoulder_tilt_trans" type="pr2_mechanism_model/SimpleTransmission">
      <actuator name="shoulder_tilt_motor"/>
      <joint name="shoulder_tilting_joint"/>
      <mechanicalReduction>1.0</mechanicalReduction>
    </transmission>

    <joint name="laser_tilt_fixed_joint" type="fixed">
      <origin xyz="0.0803 0 0.024"/>
      <parent link="shoulder_tilt_end"/>
      <child link="shoulder_tilting_laser"/>
    </joint>

    <link name="shoulder_tilting_laser">
      <inertial>
        <mass value="0.2"/>
        <cuboid_inertia_def length="0.07" width="0.07" height="0.07"
                            mass="0.2"/>
      </inertial>
      <visual>
        <origin xyz="0 0 -0.035" rpy="0 0 0"/>
        <geometry>
          <cylinder length="0.06" radius="0.025"/>
        </geometry>
        <material name="Black"/>
      </visual>
      <collision>
        <origin xyz="0 0 0" rpy="0 0 0"/>
        <geometry>
          <cylinder length="0.08" radius="0.025"/>
        </geometry>
      </collision>
    </link>
    <gazebo reference="shoulder_tilting_laser">
      <material value="Gazebo/Black"/>
    </gazebo>

    <laser_sensor_utm30lx name="shoulder_tilting_laser_sensor"
                          link="shoulder_tilting_laser">
      <origin xyz="0 0 0" rpy="0 0 0"/>
    </laser_sensor_utm30lx>
  </macro>
</robot>
