<?xml version="1.0"?>
<robot xmlns:sensor="http://playerstage.sourceforge.net/gazebo/xmlschema/#sensor"
       xmlns:controller="http://playerstage.sourceforge.net/gazebo/xmlschema/#controller"
       xmlns:interface="http://playerstage.sourceforge.net/gazebo/xmlschema/#interface">

  <include filename="$(find ias_robot_defs)/defs/util_defs.xml"/>
  <include filename="$(find ias_robot_defs)/defs/gazebo_sensors.xml"/>  
  <include filename="$(find ias_robot_defs)/defs/b21/powercube_defs.xml"/>

  <!-- Calibration values -->
  <include filename="$(find ias_robot_defs)/calibration/default_cal.xml"/>

  <property name="shoulder_tilting_laser_base_x" value="0.152" />
  <property name="shoulder_tilting_laser_base_y" value="0.07" />
  <property name="shoulder_tilting_laser_base_z" value="-0.0575" />

  <macro name="kimp_shoulder_laser" params="parent">
    <joint name="shoulder_tilt_fixed_joint" type="fixed">
      <origin xyz="${shoulder_tilting_laser_base_x}
                   ${shoulder_tilting_laser_base_y}
                   ${shoulder_tilting_laser_base_z}"
              rpy="0 0 0"/>
      <parent link="${parent}"/>
      <child link="shoulder_tilt_base"/>
    </joint>

    <link name="shoulder_tilt_base">
      <inertial>
        <mass value="${0.5 * arm_elem_70_mass}"/>
        <cuboid_inertia_def length="0.07" width="0.07" height="0.07"
                            mass="${0.5 * arm_elem_70_mass}"/>
      </inertial>
      <visual>
        <origin xyz="0 0 0" rpy="0 0 0"/>
        <geometry>
          <box size="0.07 0.07 0.07"/>
        </geometry>
        <material name="Grey"/>
      </visual>
      <collision>
        <origin xyz="0 0 0" rpy="0 0 0"/>
        <geometry>
          <box size="0.07 0.07 0.07"/>
        </geometry>
      </collision>
    </link>
    <gazebo reference="shoulder_tilt_base">
      <material value="cube_light_gray"/>
    </gazebo>

    <joint name="shoulder_tilting_joint" type="revolute">
      <origin xyz="0 -0.070 0" rpy="0 0 0"/>
      <axis xyz="0 -1 0"/>
      <limit lower="-1.3" upper="1.3"
             effort="206" velocity="${149 * M_PI/2}"/>
      <parent link="shoulder_tilt_base"/>
      <child link="shoulder_tilt_end"/>
    </joint>

    <link name="shoulder_tilt_end">
      <inertial>
        <mass value="${0.5 * arm_elem_70_mass}"/>
        <cuboid_inertia_def length="0.07" width="0.07" height="0.07"
                            mass="${0.5 * arm_elem_70_mass}"/>
      </inertial>
      <visual>
        <origin xyz="0 0 0" rpy="0 0 0"/>
        <geometry>
          <box size="0.07 0.07 0.07"/>
        </geometry>
        <material name="Grey"/>
      </visual>
      <collision>
        <origin xyz="0 0 0" rpy="0 0 0"/>
        <geometry>
          <box size="0.07 0.07 0.07"/>
        </geometry>
      </collision>
    </link>
    <gazebo reference="shoulder_tilt_end">
      <material value="cube_light_gray"/>
    </gazebo>

    <transmission name="shoulder_tilt_trans" type="SimpleTransmission">
      <actuator name="shoulder_tilt_motor"/>
      <joint name="shoulder_tilting_joint"/>
      <mechanicalReduction>1.0</mechanicalReduction>
    </transmission>

    <joint name="laser_tilt_fixed_joint" type="fixed">
      <origin xyz="0.078 0 0.030"/>
      <parent link="shoulder_tilt_end"/>
      <child link="shoulder_tilting_laser"/>
    </joint>

    <link name="shoulder_tilting_laser">
      <inertial>
        <mass value="0.2"/>
        <cuboid_inertia_def length="0.07" width="0.07" height="0.07"
                            mass="0.2"/>
      </inertial>
      <visual>
        <origin xyz="0 0 -0.035" rpy="0 0 0"/>
        <geometry>
          <cylinder length="0.06" radius="0.025"/>
        </geometry>
        <material name="Black"/>
      </visual>
      <collision>
        <origin xyz="0 0 0" rpy="0 0 0"/>
        <geometry>
          <cylinder length="0.08" radius="0.025"/>
        </geometry>
      </collision>
    </link>
    <gazebo reference="shoulder_tilting_laser">
      <material value="Gazebo/Black"/>
    </gazebo>

    <laser_sensor_utm30lx name="shoulder_tilting_laser_sensor"
                          link="shoulder_tilting_laser">
      <origin xyz="0 0 0" rpy="0 0 0"/>
    </laser_sensor_utm30lx>
  </macro>
</robot>
